INFO 2019-04-26 08:46:18,365 basehttp 124 "GET /user/signup/ HTTP/1.1" 200 17052
INFO 2019-04-26 08:46:18,615 basehttp 124 "GET /verify/get_code/ HTTP/1.1" 200 2957
INFO 2019-04-26 08:46:59,838 basehttp 124 "GET /user/signup/ HTTP/1.1" 200 17050
INFO 2019-04-26 08:47:00,026 basehttp 124 "GET /verify/get_code/ HTTP/1.1" 200 3012
INFO 2019-04-26 08:47:05,919 basehttp 124 "POST /verify/check_code/ HTTP/1.1" 200 25
INFO 2019-04-26 08:47:40,028 basehttp 124 "GET /user/signup/ HTTP/1.1" 200 17059
INFO 2019-04-26 08:47:40,232 basehttp 124 "GET /verify/get_code/ HTTP/1.1" 200 3284
ERROR 2019-04-26 08:47:43,642 exception 118 Internal Server Error: /verify/check_code/
Traceback (most recent call last):
  File "/home/binbin/.virtualenvs/v2ex/lib/python3.6/site-packages/django/core/handlers/exception.py", line 35, in inner
    response = get_response(request)
  File "/home/binbin/.virtualenvs/v2ex/lib/python3.6/site-packages/django/core/handlers/base.py", line 128, in _get_response
    response = self.process_exception_by_middleware(e, request)
  File "/home/binbin/.virtualenvs/v2ex/lib/python3.6/site-packages/django/core/handlers/base.py", line 126, in _get_response
    response = wrapped_callback(request, *callback_args, **callback_kwargs)
  File "/home/binbin/.virtualenvs/v2ex/lib/python3.6/site-packages/django/views/generic/base.py", line 69, in view
    return self.dispatch(request, *args, **kwargs)
  File "/home/binbin/.virtualenvs/v2ex/lib/python3.6/site-packages/django/views/generic/base.py", line 89, in dispatch
    return handler(request, *args, **kwargs)
  File "/home/binbin/Desktop/Fake/verification/views.py", line 37, in post
    raise ValidationError('验证码错误')
django.core.exceptions.ValidationError: ['验证码错误']
ERROR 2019-04-26 08:47:43,678 basehttp 124 "POST /verify/check_code/ HTTP/1.1" 500 16052
INFO 2019-04-26 08:48:12,567 basehttp 124 "GET /user/signup/ HTTP/1.1" 200 17059
INFO 2019-04-26 08:48:12,734 basehttp 124 "GET /verify/get_code/ HTTP/1.1" 200 3622
INFO 2019-04-26 08:48:18,607 basehttp 124 "POST /verify/check_code/ HTTP/1.1" 200 25
INFO 2019-04-26 08:49:47,951 basehttp 124 "GET /user/signup/ HTTP/1.1" 200 17059
INFO 2019-04-26 08:49:48,257 basehttp 124 "GET /verify/get_code/ HTTP/1.1" 200 3275
INFO 2019-04-26 08:49:54,955 basehttp 124 "POST /verify/check_code/ HTTP/1.1" 200 59
INFO 2019-04-26 08:50:03,471 basehttp 124 "POST /verify/check_code/ HTTP/1.1" 200 25
WARNING 2019-04-26 11:37:14,807 base 93 Not Found: /image_codes/f3b9d72e-77e7-438e-9a4c-91e0be00cb34/
WARNING 2019-04-26 11:37:14,827 basehttp 124 "GET /image_codes/f3b9d72e-77e7-438e-9a4c-91e0be00cb34/ HTTP/1.1" 404 2402
WARNING 2019-04-26 11:37:40,744 base 93 Not Found: /image_codes/b34bde02-37a2-4718-b7e7-2720d7a0ea23/
WARNING 2019-04-26 11:37:40,745 basehttp 124 "GET /image_codes/b34bde02-37a2-4718-b7e7-2720d7a0ea23/ HTTP/1.1" 404 2402
INFO 2019-04-26 11:39:53,574 basehttp 124 "GET /user/signup/ HTTP/1.1" 200 17059
INFO 2019-04-26 11:39:53,820 basehttp 124 "GET /verify/get_code/ HTTP/1.1" 200 2971
INFO 2019-04-26 11:39:55,637 basehttp 124 "GET /user/signup/ HTTP/1.1" 200 17059
INFO 2019-04-26 11:39:55,785 basehttp 124 "GET /verify/get_code/ HTTP/1.1" 200 3125
INFO 2019-04-26 11:40:02,730 basehttp 124 "POST /user/check_mobile/ HTTP/1.1" 200 79
INFO 2019-04-26 11:40:06,909 basehttp 124 "POST /user/check_mobile/ HTTP/1.1" 200 79
INFO 2019-04-26 11:40:11,368 basehttp 124 "POST /verify/check_code/ HTTP/1.1" 200 59
INFO 2019-04-26 11:40:31,120 basehttp 124 "GET /user/signup/ HTTP/1.1" 200 17035
INFO 2019-04-26 11:40:31,245 basehttp 124 "GET /verify/get_code/ HTTP/1.1" 200 3418
INFO 2019-04-26 11:40:35,105 basehttp 124 "POST /verify/check_code/ HTTP/1.1" 200 59
INFO 2019-04-26 11:40:40,069 basehttp 124 "POST /verify/check_code/ HTTP/1.1" 200 53
INFO 2019-04-26 11:40:49,615 basehttp 124 "POST /verify/check_code/ HTTP/1.1" 200 53
INFO 2019-04-26 11:41:10,115 basehttp 124 "GET /user/signup/ HTTP/1.1" 200 17035
INFO 2019-04-26 11:41:10,295 basehttp 124 "GET /verify/get_code/ HTTP/1.1" 200 3144
INFO 2019-04-26 11:41:11,214 basehttp 124 "GET /user/signup/ HTTP/1.1" 200 17035
INFO 2019-04-26 11:41:11,842 basehttp 124 "GET /verify/get_code/ HTTP/1.1" 200 3114
INFO 2019-04-26 11:41:15,438 basehttp 124 "POST /verify/check_code/ HTTP/1.1" 200 59
INFO 2019-04-26 11:41:19,689 basehttp 124 "POST /verify/check_code/ HTTP/1.1" 200 59
INFO 2019-04-26 11:41:29,096 basehttp 124 "POST /verify/check_code/ HTTP/1.1" 200 59
INFO 2019-04-26 11:43:46,920 basehttp 124 "GET /verify/get_code/? HTTP/1.1" 200 3158
INFO 2019-04-26 11:43:57,902 basehttp 124 "POST /verify/check_code/ HTTP/1.1" 200 59
INFO 2019-04-26 11:44:05,496 basehttp 124 "POST /verify/check_code/ HTTP/1.1" 200 59
INFO 2019-04-26 11:44:10,758 basehttp 124 "GET /verify/get_code/?? HTTP/1.1" 200 3278
INFO 2019-04-26 11:44:17,769 basehttp 124 "POST /verify/check_code/ HTTP/1.1" 200 59
INFO 2019-04-26 11:44:45,028 basehttp 124 "GET /user/signup/ HTTP/1.1" 200 17035
INFO 2019-04-26 11:44:45,190 basehttp 124 "GET /verify/get_code/ HTTP/1.1" 200 3415
INFO 2019-04-26 11:44:46,101 basehttp 124 "GET /user/signup/ HTTP/1.1" 200 17035
INFO 2019-04-26 11:44:46,389 basehttp 124 "GET /verify/get_code/ HTTP/1.1" 200 3016
INFO 2019-04-26 11:44:52,661 basehttp 124 "POST /verify/check_code/ HTTP/1.1" 200 59
INFO 2019-04-26 11:44:55,016 basehttp 124 "POST /verify/check_code/ HTTP/1.1" 200 59
INFO 2019-04-26 11:45:36,258 basehttp 124 "GET /user/signup/ HTTP/1.1" 200 17035
INFO 2019-04-26 11:45:36,392 basehttp 124 "GET /verify/get_code/ HTTP/1.1" 200 3478
INFO 2019-04-26 11:45:38,065 basehttp 124 "GET /user/signup/ HTTP/1.1" 200 17035
INFO 2019-04-26 11:45:38,186 basehttp 124 "GET /verify/get_code/ HTTP/1.1" 200 3218
INFO 2019-04-26 11:45:40,482 basehttp 124 "POST /verify/check_code/ HTTP/1.1" 200 59
INFO 2019-04-26 11:45:42,362 basehttp 124 "POST /verify/check_code/ HTTP/1.1" 200 59
INFO 2019-04-26 11:45:47,146 basehttp 124 "POST /verify/check_code/ HTTP/1.1" 200 97
INFO 2019-04-26 11:47:11,997 basehttp 124 "POST /user/signup/ HTTP/1.1" 200 12381
WARNING 2019-04-26 11:47:12,083 base 94 Method Not Allowed (GET): /verify/check_code/
WARNING 2019-04-26 11:47:12,085 basehttp 124 "GET /verify/check_code/ HTTP/1.1" 405 0
INFO 2019-04-26 11:47:16,482 basehttp 124 "GET /user/signup/ HTTP/1.1" 200 17035
INFO 2019-04-26 11:49:44,536 basehttp 124 "GET /user/signup/ HTTP/1.1" 200 17035
INFO 2019-04-26 11:49:44,693 basehttp 124 "GET /verify/get_code/ HTTP/1.1" 200 3490
INFO 2019-04-26 12:01:00,417 basehttp 124 "GET /user/signup/ HTTP/1.1" 200 17035
INFO 2019-04-26 12:01:00,577 basehttp 124 "GET /verify/get_code/ HTTP/1.1" 200 3151
INFO 2019-04-26 12:01:16,858 basehttp 124 "GET /user/signup/ HTTP/1.1" 200 17035
INFO 2019-04-26 12:01:20,017 basehttp 124 "GET /user/signup/ HTTP/1.1" 200 17035
INFO 2019-04-26 12:01:20,140 basehttp 124 "GET /verify/get_code/ HTTP/1.1" 200 3636
INFO 2019-04-26 12:01:22,657 basehttp 124 "POST /user/check_username/ HTTP/1.1" 200 27
ERROR 2019-04-26 12:01:25,248 exception 118 Internal Server Error: /user/signup/
Traceback (most recent call last):
  File "/home/binbin/.virtualenvs/v2ex/lib/python3.6/site-packages/django/core/handlers/exception.py", line 35, in inner
    response = get_response(request)
  File "/home/binbin/.virtualenvs/v2ex/lib/python3.6/site-packages/django/core/handlers/base.py", line 139, in _get_response
    "returned None instead." % (callback.__module__, view_name)
ValueError: The view users.views.SignupView didn't return an HttpResponse object. It returned None instead.
ERROR 2019-04-26 12:01:25,382 basehttp 124 "POST /user/signup/ HTTP/1.1" 500 61870
INFO 2019-04-26 12:03:24,565 basehttp 124 "GET /user/signup/ HTTP/1.1" 200 16863
INFO 2019-04-26 12:03:24,715 basehttp 124 "GET /verify/get_code/ HTTP/1.1" 200 3030
INFO 2019-04-26 12:03:27,542 basehttp 124 "POST /user/check_username/ HTTP/1.1" 200 27
ERROR 2019-04-26 12:03:30,946 exception 118 Internal Server Error: /user/signup/
Traceback (most recent call last):
  File "/home/binbin/.virtualenvs/v2ex/lib/python3.6/site-packages/django/core/handlers/exception.py", line 35, in inner
    response = get_response(request)
  File "/home/binbin/.virtualenvs/v2ex/lib/python3.6/site-packages/django/core/handlers/base.py", line 139, in _get_response
    "returned None instead." % (callback.__module__, view_name)
ValueError: The view users.views.SignupView didn't return an HttpResponse object. It returned None instead.
ERROR 2019-04-26 12:03:31,125 basehttp 124 "POST /user/signup/ HTTP/1.1" 500 61870
INFO 2019-04-26 12:04:15,796 basehttp 124 "GET /user/signup/ HTTP/1.1" 200 16863
INFO 2019-04-26 12:04:15,950 basehttp 124 "GET /verify/get_code/ HTTP/1.1" 200 3216
INFO 2019-04-26 12:04:17,256 basehttp 124 "GET /user/signup/ HTTP/1.1" 200 16863
INFO 2019-04-26 12:04:17,433 basehttp 124 "GET /verify/get_code/ HTTP/1.1" 200 2922
INFO 2019-04-26 12:04:20,786 basehttp 124 "POST /user/check_username/ HTTP/1.1" 200 27
INFO 2019-04-26 12:04:22,024 basehttp 124 "POST /user/signup/ HTTP/1.1" 200 16863
INFO 2019-04-26 12:04:22,110 basehttp 124 "GET /verify/get_code/ HTTP/1.1" 200 3366
INFO 2019-04-26 12:04:44,206 basehttp 124 "POST /user/check_username/ HTTP/1.1" 200 27
INFO 2019-04-26 12:04:46,053 basehttp 124 "POST /user/signup/ HTTP/1.1" 200 16863
INFO 2019-04-26 12:04:46,144 basehttp 124 "GET /verify/get_code/ HTTP/1.1" 200 3454
INFO 2019-04-26 12:04:48,304 basehttp 124 "POST /user/check_username/ HTTP/1.1" 200 27
INFO 2019-04-26 12:04:49,599 basehttp 124 "POST /user/signup/ HTTP/1.1" 200 16863
INFO 2019-04-26 12:04:49,683 basehttp 124 "GET /verify/get_code/ HTTP/1.1" 200 3101
INFO 2019-04-26 12:04:51,644 basehttp 124 "POST /user/check_username/ HTTP/1.1" 200 27
INFO 2019-04-26 12:04:52,482 basehttp 124 "POST /user/signup/ HTTP/1.1" 200 16863
INFO 2019-04-26 12:04:52,594 basehttp 124 "GET /verify/get_code/ HTTP/1.1" 200 3280
INFO 2019-04-26 12:05:57,507 basehttp 124 "GET /user/signup/ HTTP/1.1" 200 16863
INFO 2019-04-26 12:05:57,715 basehttp 124 "GET /verify/get_code/ HTTP/1.1" 200 3565
INFO 2019-04-26 12:06:00,175 basehttp 124 "POST /user/check_username/ HTTP/1.1" 200 27
ERROR 2019-04-26 12:06:01,760 exception 118 Internal Server Error: /user/signup/
Traceback (most recent call last):
  File "/home/binbin/.virtualenvs/v2ex/lib/python3.6/site-packages/django/core/handlers/exception.py", line 35, in inner
    response = get_response(request)
  File "/home/binbin/.virtualenvs/v2ex/lib/python3.6/site-packages/django/core/handlers/base.py", line 128, in _get_response
    response = self.process_exception_by_middleware(e, request)
  File "/home/binbin/.virtualenvs/v2ex/lib/python3.6/site-packages/django/core/handlers/base.py", line 126, in _get_response
    response = wrapped_callback(request, *callback_args, **callback_kwargs)
  File "/home/binbin/.virtualenvs/v2ex/lib/python3.6/site-packages/django/views/generic/base.py", line 69, in view
    return self.dispatch(request, *args, **kwargs)
  File "/home/binbin/.virtualenvs/v2ex/lib/python3.6/site-packages/django/views/generic/base.py", line 89, in dispatch
    return handler(request, *args, **kwargs)
  File "/home/binbin/Desktop/Fake/users/views.py", line 68, in post
    return render(request, locals())
  File "/home/binbin/.virtualenvs/v2ex/lib/python3.6/site-packages/django/shortcuts.py", line 36, in render
    content = loader.render_to_string(template_name, context, request, using=using)
  File "/home/binbin/.virtualenvs/v2ex/lib/python3.6/site-packages/django/template/loader.py", line 61, in render_to_string
    template = get_template(template_name, using=using)
  File "/home/binbin/.virtualenvs/v2ex/lib/python3.6/site-packages/django/template/loader.py", line 19, in get_template
    raise TemplateDoesNotExist(template_name, chain=chain)
django.template.exceptions.TemplateDoesNotExist: {'obj': <FormTable bound=True, valid=False, fields=(username;password;email;mobile)>, 'request': <WSGIRequest: POST '/user/signup/'>, 'self': <users.views.SignupView object at 0x7f42ad5ef978>}
ERROR 2019-04-26 12:06:01,975 basehttp 124 "POST /user/signup/ HTTP/1.1" 500 98106
INFO 2019-04-26 12:10:42,317 basehttp 124 "GET /user/signup/ HTTP/1.1" 200 17039
INFO 2019-04-26 12:10:42,434 basehttp 124 "GET /verify/get_code/ HTTP/1.1" 200 3095
INFO 2019-04-26 12:10:45,076 basehttp 124 "POST /user/check_username/ HTTP/1.1" 200 27
ERROR 2019-04-26 12:10:46,222 exception 118 Internal Server Error: /user/signup/
Traceback (most recent call last):
  File "/home/binbin/.virtualenvs/v2ex/lib/python3.6/site-packages/django/core/handlers/exception.py", line 35, in inner
    response = get_response(request)
  File "/home/binbin/.virtualenvs/v2ex/lib/python3.6/site-packages/django/core/handlers/base.py", line 128, in _get_response
    response = self.process_exception_by_middleware(e, request)
  File "/home/binbin/.virtualenvs/v2ex/lib/python3.6/site-packages/django/core/handlers/base.py", line 126, in _get_response
    response = wrapped_callback(request, *callback_args, **callback_kwargs)
  File "/home/binbin/.virtualenvs/v2ex/lib/python3.6/site-packages/django/views/generic/base.py", line 69, in view
    return self.dispatch(request, *args, **kwargs)
  File "/home/binbin/.virtualenvs/v2ex/lib/python3.6/site-packages/django/views/generic/base.py", line 89, in dispatch
    return handler(request, *args, **kwargs)
  File "/home/binbin/Desktop/Fake/users/views.py", line 68, in post
    return render(request, locals())
  File "/home/binbin/.virtualenvs/v2ex/lib/python3.6/site-packages/django/shortcuts.py", line 36, in render
    content = loader.render_to_string(template_name, context, request, using=using)
  File "/home/binbin/.virtualenvs/v2ex/lib/python3.6/site-packages/django/template/loader.py", line 61, in render_to_string
    template = get_template(template_name, using=using)
  File "/home/binbin/.virtualenvs/v2ex/lib/python3.6/site-packages/django/template/loader.py", line 19, in get_template
    raise TemplateDoesNotExist(template_name, chain=chain)
django.template.exceptions.TemplateDoesNotExist: {'obj': <FormTable bound=True, valid=False, fields=(username;password;email;mobile)>, 'request': <WSGIRequest: POST '/user/signup/'>, 'self': <users.views.SignupView object at 0x7f42ad587f98>}
ERROR 2019-04-26 12:10:46,353 basehttp 124 "POST /user/signup/ HTTP/1.1" 500 98106
INFO 2019-04-26 12:15:38,591 basehttp 124 "GET /user/signup/ HTTP/1.1" 200 17069
INFO 2019-04-26 12:15:38,768 basehttp 124 "GET /verify/get_code/ HTTP/1.1" 200 3090
INFO 2019-04-26 12:15:40,541 basehttp 124 "GET /user/signup/ HTTP/1.1" 200 17069
INFO 2019-04-26 12:15:40,652 basehttp 124 "GET /verify/get_code/ HTTP/1.1" 200 3456
INFO 2019-04-26 12:15:42,960 basehttp 124 "POST /user/check_username/ HTTP/1.1" 200 27
ERROR 2019-04-26 12:15:44,276 exception 118 Internal Server Error: /user/signup/
Traceback (most recent call last):
  File "/home/binbin/.virtualenvs/v2ex/lib/python3.6/site-packages/django/core/handlers/exception.py", line 35, in inner
    response = get_response(request)
  File "/home/binbin/.virtualenvs/v2ex/lib/python3.6/site-packages/django/core/handlers/base.py", line 128, in _get_response
    response = self.process_exception_by_middleware(e, request)
  File "/home/binbin/.virtualenvs/v2ex/lib/python3.6/site-packages/django/core/handlers/base.py", line 126, in _get_response
    response = wrapped_callback(request, *callback_args, **callback_kwargs)
  File "/home/binbin/.virtualenvs/v2ex/lib/python3.6/site-packages/django/views/generic/base.py", line 69, in view
    return self.dispatch(request, *args, **kwargs)
  File "/home/binbin/.virtualenvs/v2ex/lib/python3.6/site-packages/django/views/generic/base.py", line 89, in dispatch
    return handler(request, *args, **kwargs)
  File "/home/binbin/Desktop/Fake/users/views.py", line 68, in post
    return render(request, locals())
  File "/home/binbin/.virtualenvs/v2ex/lib/python3.6/site-packages/django/shortcuts.py", line 36, in render
    content = loader.render_to_string(template_name, context, request, using=using)
  File "/home/binbin/.virtualenvs/v2ex/lib/python3.6/site-packages/django/template/loader.py", line 61, in render_to_string
    template = get_template(template_name, using=using)
  File "/home/binbin/.virtualenvs/v2ex/lib/python3.6/site-packages/django/template/loader.py", line 19, in get_template
    raise TemplateDoesNotExist(template_name, chain=chain)
django.template.exceptions.TemplateDoesNotExist: {'obj': <FormTable bound=True, valid=False, fields=(username;password;email;mobile)>, 'request': <WSGIRequest: POST '/user/signup/'>, 'self': <users.views.SignupView object at 0x7f42ad30cdd8>}
ERROR 2019-04-26 12:15:44,445 basehttp 124 "POST /user/signup/ HTTP/1.1" 500 98106
INFO 2019-04-26 12:24:03,238 basehttp 124 "GET /user/signup/ HTTP/1.1" 200 17721
INFO 2019-04-26 12:24:03,399 basehttp 124 "GET /verify/get_code/ HTTP/1.1" 200 2814
INFO 2019-04-26 12:24:09,612 basehttp 124 "POST /user/check_mobile/ HTTP/1.1" 200 79
ERROR 2019-04-26 12:24:11,368 exception 118 Internal Server Error: /user/signup/
Traceback (most recent call last):
  File "/home/binbin/.virtualenvs/v2ex/lib/python3.6/site-packages/django/core/handlers/exception.py", line 35, in inner
    response = get_response(request)
  File "/home/binbin/.virtualenvs/v2ex/lib/python3.6/site-packages/django/core/handlers/base.py", line 128, in _get_response
    response = self.process_exception_by_middleware(e, request)
  File "/home/binbin/.virtualenvs/v2ex/lib/python3.6/site-packages/django/core/handlers/base.py", line 126, in _get_response
    response = wrapped_callback(request, *callback_args, **callback_kwargs)
  File "/home/binbin/.virtualenvs/v2ex/lib/python3.6/site-packages/django/views/generic/base.py", line 69, in view
    return self.dispatch(request, *args, **kwargs)
  File "/home/binbin/.virtualenvs/v2ex/lib/python3.6/site-packages/django/views/generic/base.py", line 89, in dispatch
    return handler(request, *args, **kwargs)
  File "/home/binbin/Desktop/Fake/users/views.py", line 68, in post
    return render(request, locals())
  File "/home/binbin/.virtualenvs/v2ex/lib/python3.6/site-packages/django/shortcuts.py", line 36, in render
    content = loader.render_to_string(template_name, context, request, using=using)
  File "/home/binbin/.virtualenvs/v2ex/lib/python3.6/site-packages/django/template/loader.py", line 61, in render_to_string
    template = get_template(template_name, using=using)
  File "/home/binbin/.virtualenvs/v2ex/lib/python3.6/site-packages/django/template/loader.py", line 19, in get_template
    raise TemplateDoesNotExist(template_name, chain=chain)
django.template.exceptions.TemplateDoesNotExist: {'obj': <FormTable bound=True, valid=False, fields=(username;password;email;mobile)>, 'request': <WSGIRequest: POST '/user/signup/'>, 'self': <users.views.SignupView object at 0x7f42ad30cac8>}
ERROR 2019-04-26 12:24:11,508 basehttp 124 "POST /user/signup/ HTTP/1.1" 500 98105
INFO 2019-04-26 12:29:08,645 basehttp 124 "GET /user/signup/ HTTP/1.1" 200 17728
INFO 2019-04-26 12:29:08,790 basehttp 124 "GET /verify/get_code/ HTTP/1.1" 200 3256
ERROR 2019-04-26 12:29:14,485 exception 118 Internal Server Error: /user/signup/
Traceback (most recent call last):
  File "/home/binbin/.virtualenvs/v2ex/lib/python3.6/site-packages/django/core/handlers/exception.py", line 35, in inner
    response = get_response(request)
  File "/home/binbin/.virtualenvs/v2ex/lib/python3.6/site-packages/django/core/handlers/base.py", line 128, in _get_response
    response = self.process_exception_by_middleware(e, request)
  File "/home/binbin/.virtualenvs/v2ex/lib/python3.6/site-packages/django/core/handlers/base.py", line 126, in _get_response
    response = wrapped_callback(request, *callback_args, **callback_kwargs)
  File "/home/binbin/.virtualenvs/v2ex/lib/python3.6/site-packages/django/views/generic/base.py", line 69, in view
    return self.dispatch(request, *args, **kwargs)
  File "/home/binbin/.virtualenvs/v2ex/lib/python3.6/site-packages/django/views/generic/base.py", line 89, in dispatch
    return handler(request, *args, **kwargs)
  File "/home/binbin/Desktop/Fake/users/views.py", line 68, in post
    return render(request, locals())
  File "/home/binbin/.virtualenvs/v2ex/lib/python3.6/site-packages/django/shortcuts.py", line 36, in render
    content = loader.render_to_string(template_name, context, request, using=using)
  File "/home/binbin/.virtualenvs/v2ex/lib/python3.6/site-packages/django/template/loader.py", line 61, in render_to_string
    template = get_template(template_name, using=using)
  File "/home/binbin/.virtualenvs/v2ex/lib/python3.6/site-packages/django/template/loader.py", line 19, in get_template
    raise TemplateDoesNotExist(template_name, chain=chain)
django.template.exceptions.TemplateDoesNotExist: {'obj': <FormTable bound=True, valid=False, fields=(username;password;email;mobile)>, 'request': <WSGIRequest: POST '/user/signup/'>, 'self': <users.views.SignupView object at 0x7f42ad5a1748>}
ERROR 2019-04-26 12:29:14,674 basehttp 124 "POST /user/signup/ HTTP/1.1" 500 98105
INFO 2019-04-26 12:30:10,750 basehttp 124 "GET /user/signup/ HTTP/1.1" 200 17735
INFO 2019-04-26 12:30:10,987 basehttp 124 "GET /verify/get_code/ HTTP/1.1" 200 3250
ERROR 2019-04-26 12:30:17,690 exception 118 Internal Server Error: /user/signup/
Traceback (most recent call last):
  File "/home/binbin/.virtualenvs/v2ex/lib/python3.6/site-packages/django/core/handlers/exception.py", line 35, in inner
    response = get_response(request)
  File "/home/binbin/.virtualenvs/v2ex/lib/python3.6/site-packages/django/core/handlers/base.py", line 128, in _get_response
    response = self.process_exception_by_middleware(e, request)
  File "/home/binbin/.virtualenvs/v2ex/lib/python3.6/site-packages/django/core/handlers/base.py", line 126, in _get_response
    response = wrapped_callback(request, *callback_args, **callback_kwargs)
  File "/home/binbin/.virtualenvs/v2ex/lib/python3.6/site-packages/django/views/generic/base.py", line 69, in view
    return self.dispatch(request, *args, **kwargs)
  File "/home/binbin/.virtualenvs/v2ex/lib/python3.6/site-packages/django/views/generic/base.py", line 89, in dispatch
    return handler(request, *args, **kwargs)
  File "/home/binbin/Desktop/Fake/users/views.py", line 68, in post
    return render(request, locals())
  File "/home/binbin/.virtualenvs/v2ex/lib/python3.6/site-packages/django/shortcuts.py", line 36, in render
    content = loader.render_to_string(template_name, context, request, using=using)
  File "/home/binbin/.virtualenvs/v2ex/lib/python3.6/site-packages/django/template/loader.py", line 61, in render_to_string
    template = get_template(template_name, using=using)
  File "/home/binbin/.virtualenvs/v2ex/lib/python3.6/site-packages/django/template/loader.py", line 19, in get_template
    raise TemplateDoesNotExist(template_name, chain=chain)
django.template.exceptions.TemplateDoesNotExist: {'obj': <FormTable bound=True, valid=False, fields=(username;password;email;mobile)>, 'request': <WSGIRequest: POST '/user/signup/'>, 'self': <users.views.SignupView object at 0x7f42ad312f98>}
ERROR 2019-04-26 12:30:17,883 basehttp 124 "POST /user/signup/ HTTP/1.1" 500 98105
INFO 2019-04-26 12:35:45,489 basehttp 124 "GET /user/signup/ HTTP/1.1" 200 17723
INFO 2019-04-26 12:35:45,618 basehttp 124 "GET /verify/get_code/ HTTP/1.1" 200 3587
ERROR 2019-04-26 12:35:48,719 exception 118 Internal Server Error: /user/signup/
Traceback (most recent call last):
  File "/home/binbin/.virtualenvs/v2ex/lib/python3.6/site-packages/django/core/handlers/exception.py", line 35, in inner
    response = get_response(request)
  File "/home/binbin/.virtualenvs/v2ex/lib/python3.6/site-packages/django/core/handlers/base.py", line 128, in _get_response
    response = self.process_exception_by_middleware(e, request)
  File "/home/binbin/.virtualenvs/v2ex/lib/python3.6/site-packages/django/core/handlers/base.py", line 126, in _get_response
    response = wrapped_callback(request, *callback_args, **callback_kwargs)
  File "/home/binbin/.virtualenvs/v2ex/lib/python3.6/site-packages/django/views/generic/base.py", line 69, in view
    return self.dispatch(request, *args, **kwargs)
  File "/home/binbin/.virtualenvs/v2ex/lib/python3.6/site-packages/django/views/generic/base.py", line 89, in dispatch
    return handler(request, *args, **kwargs)
  File "/home/binbin/Desktop/Fake/users/views.py", line 68, in post
    return render(request, locals())
  File "/home/binbin/.virtualenvs/v2ex/lib/python3.6/site-packages/django/shortcuts.py", line 36, in render
    content = loader.render_to_string(template_name, context, request, using=using)
  File "/home/binbin/.virtualenvs/v2ex/lib/python3.6/site-packages/django/template/loader.py", line 61, in render_to_string
    template = get_template(template_name, using=using)
  File "/home/binbin/.virtualenvs/v2ex/lib/python3.6/site-packages/django/template/loader.py", line 19, in get_template
    raise TemplateDoesNotExist(template_name, chain=chain)
django.template.exceptions.TemplateDoesNotExist: {'obj': <FormTable bound=True, valid=False, fields=(username;password;email;mobile)>, 'request': <WSGIRequest: POST '/user/signup/'>, 'self': <users.views.SignupView object at 0x7f42ad319400>}
ERROR 2019-04-26 12:35:48,897 basehttp 124 "POST /user/signup/ HTTP/1.1" 500 98105
INFO 2019-04-26 12:36:01,553 basehttp 124 "GET /user/signup/ HTTP/1.1" 200 17723
INFO 2019-04-26 12:36:05,338 basehttp 124 "GET /user/signup/ HTTP/1.1" 200 17723
INFO 2019-04-26 12:36:05,504 basehttp 124 "GET /verify/get_code/ HTTP/1.1" 200 3006
ERROR 2019-04-26 12:36:10,020 exception 118 Internal Server Error: /user/signup/
Traceback (most recent call last):
  File "/home/binbin/.virtualenvs/v2ex/lib/python3.6/site-packages/django/core/handlers/exception.py", line 35, in inner
    response = get_response(request)
  File "/home/binbin/.virtualenvs/v2ex/lib/python3.6/site-packages/django/core/handlers/base.py", line 139, in _get_response
    "returned None instead." % (callback.__module__, view_name)
ValueError: The view users.views.SignupView didn't return an HttpResponse object. It returned None instead.
ERROR 2019-04-26 12:36:10,138 basehttp 124 "POST /user/signup/ HTTP/1.1" 500 61872
INFO 2019-04-26 12:36:39,231 basehttp 124 "GET /user/signup/ HTTP/1.1" 200 17723
INFO 2019-04-26 12:36:39,378 basehttp 124 "GET /verify/get_code/ HTTP/1.1" 200 3012
INFO 2019-04-26 12:36:42,999 basehttp 124 "POST /user/signup/ HTTP/1.1" 200 12381
WARNING 2019-04-26 12:36:43,067 base 94 Method Not Allowed (GET): /verify/check_code/
WARNING 2019-04-26 12:36:43,068 basehttp 124 "GET /verify/check_code/ HTTP/1.1" 405 0
INFO 2019-04-26 12:37:03,497 basehttp 124 "GET /user/signup/ HTTP/1.1" 200 17723
INFO 2019-04-26 12:39:14,639 basehttp 124 "GET /index/ HTTP/1.1" 200 2
WARNING 2019-04-26 12:39:18,045 base 94 Method Not Allowed (GET): /user/signin/
WARNING 2019-04-26 12:39:18,046 basehttp 124 "GET /user/signin/ HTTP/1.1" 405 0
INFO 2019-04-26 12:39:23,015 basehttp 124 "GET /user/signup/ HTTP/1.1" 200 17723
INFO 2019-04-26 12:39:23,198 basehttp 124 "GET /verify/get_code/ HTTP/1.1" 200 3148
INFO 2019-04-26 12:40:16,884 basehttp 124 "GET /user/signup/ HTTP/1.1" 200 17722
INFO 2019-04-26 12:40:17,033 basehttp 124 "GET /verify/get_code/ HTTP/1.1" 200 3047
INFO 2019-04-26 12:40:21,032 basehttp 124 "POST /user/signup/ HTTP/1.1" 200 12381
WARNING 2019-04-26 12:40:21,177 base 94 Method Not Allowed (GET): /verify/check_code/
WARNING 2019-04-26 12:40:21,179 basehttp 124 "GET /verify/check_code/ HTTP/1.1" 405 0
INFO 2019-04-26 12:40:25,679 basehttp 124 "GET /user/signup/ HTTP/1.1" 200 17722
INFO 2019-04-26 12:43:48,542 basehttp 124 "GET /user/signup/ HTTP/1.1" 200 17740
INFO 2019-04-26 12:43:48,672 basehttp 124 "GET /verify/get_code/ HTTP/1.1" 200 3205
INFO 2019-04-26 12:43:51,537 basehttp 124 "POST /user/signup/ HTTP/1.1" 200 12381
WARNING 2019-04-26 12:43:51,655 base 94 Method Not Allowed (GET): /verify/check_code/
WARNING 2019-04-26 12:43:51,657 basehttp 124 "GET /verify/check_code/ HTTP/1.1" 405 0
INFO 2019-04-26 12:43:55,403 basehttp 124 "GET /user/signup/ HTTP/1.1" 200 17740
INFO 2019-04-26 12:43:57,091 basehttp 124 "GET /user/signup/ HTTP/1.1" 200 17740
INFO 2019-04-26 12:43:57,259 basehttp 124 "GET /verify/get_code/ HTTP/1.1" 200 2525
INFO 2019-04-26 12:44:39,361 basehttp 124 "GET /user/signup/ HTTP/1.1" 200 17747
INFO 2019-04-26 12:44:39,606 basehttp 124 "GET /verify/get_code/ HTTP/1.1" 200 3281
INFO 2019-04-26 12:45:31,432 basehttp 124 "POST /user/signup/ HTTP/1.1" 200 12381
WARNING 2019-04-26 12:45:31,542 base 94 Method Not Allowed (GET): /verify/check_code/
WARNING 2019-04-26 12:45:31,544 basehttp 124 "GET /verify/check_code/ HTTP/1.1" 405 0
INFO 2019-04-26 12:45:36,332 basehttp 124 "GET /user/signup/ HTTP/1.1" 200 17747
INFO 2019-04-26 13:25:04,212 basehttp 124 "GET /user/signup/ HTTP/1.1" 200 17747
INFO 2019-04-26 13:25:04,484 basehttp 124 "GET /verify/get_code/ HTTP/1.1" 200 3792
INFO 2019-04-26 13:25:07,038 basehttp 124 "POST /user/check_username/ HTTP/1.1" 200 27
INFO 2019-04-26 13:25:08,301 basehttp 124 "POST /user/signup/ HTTP/1.1" 200 17747
INFO 2019-04-26 13:25:08,447 basehttp 124 "GET /verify/get_code/ HTTP/1.1" 200 2949
INFO 2019-04-26 13:25:14,758 basehttp 124 "POST /user/check_username/ HTTP/1.1" 200 27
INFO 2019-04-26 13:25:18,540 basehttp 124 "POST /user/check_mobile/ HTTP/1.1" 200 79
INFO 2019-04-26 13:25:18,700 basehttp 124 "POST /user/signup/ HTTP/1.1" 200 17747
INFO 2019-04-26 13:25:18,823 basehttp 124 "GET /verify/get_code/ HTTP/1.1" 200 3084
INFO 2019-04-26 13:25:35,356 basehttp 124 "GET /user/signup/ HTTP/1.1" 200 17747
INFO 2019-04-26 13:25:35,506 basehttp 124 "GET /verify/get_code/ HTTP/1.1" 200 2830
INFO 2019-04-26 13:25:40,181 basehttp 124 "POST /user/signup/ HTTP/1.1" 200 17747
INFO 2019-04-26 13:25:40,430 basehttp 124 "GET /verify/get_code/ HTTP/1.1" 200 3072
INFO 2019-04-26 13:32:32,460 basehttp 124 "POST /user/signup/ HTTP/1.1" 200 17759
INFO 2019-04-26 13:32:32,661 basehttp 124 "GET /verify/get_code/ HTTP/1.1" 200 3558
INFO 2019-04-26 13:32:35,390 basehttp 124 "GET /user/signup/ HTTP/1.1" 200 17759
INFO 2019-04-26 13:32:35,576 basehttp 124 "GET /verify/get_code/ HTTP/1.1" 200 3836
INFO 2019-04-26 13:32:37,930 basehttp 124 "POST /user/signup/ HTTP/1.1" 200 17759
INFO 2019-04-26 13:32:38,221 basehttp 124 "GET /verify/get_code/ HTTP/1.1" 200 3005
WARNING 2019-04-26 13:37:56,078 base 94 Method Not Allowed (GET): /user/signin/
WARNING 2019-04-26 13:37:56,079 basehttp 124 "GET /user/signin/ HTTP/1.1" 405 0
WARNING 2019-04-26 13:38:01,787 base 94 Method Not Allowed (GET): /user/signin/
WARNING 2019-04-26 13:38:01,788 basehttp 124 "GET /user/signin/ HTTP/1.1" 405 0
INFO 2019-04-26 13:38:26,814 basehttp 124 "GET /user/signup/ HTTP/1.1" 200 17740
INFO 2019-04-26 13:38:26,958 basehttp 124 "GET /verify/get_code/ HTTP/1.1" 200 3344
INFO 2019-04-26 13:38:29,422 basehttp 124 "GET /user/signin/ HTTP/1.1" 200 12381
WARNING 2019-04-26 13:38:29,500 base 94 Method Not Allowed (GET): /verify/check_code/
WARNING 2019-04-26 13:38:29,505 basehttp 124 "GET /verify/check_code/ HTTP/1.1" 405 0
INFO 2019-04-26 13:39:25,093 basehttp 124 "GET /user/signin/ HTTP/1.1" 200 12379
INFO 2019-04-26 13:39:25,256 basehttp 124 "GET /verify/get_code/ HTTP/1.1" 200 2941
INFO 2019-04-26 13:39:27,100 basehttp 124 "GET /verify/get_code/? HTTP/1.1" 200 2960
INFO 2019-04-26 13:39:27,684 basehttp 124 "GET /verify/get_code/?? HTTP/1.1" 200 3416
INFO 2019-04-26 13:41:36,495 basehttp 124 "GET /user/signin/ HTTP/1.1" 200 12418
INFO 2019-04-26 13:41:36,646 basehttp 124 "GET /verify/get_code/ HTTP/1.1" 200 3338
INFO 2019-04-26 13:41:38,264 basehttp 124 "GET /verify/get_code/? HTTP/1.1" 200 3285
INFO 2019-04-26 13:41:38,908 basehttp 124 "GET /verify/get_code/?? HTTP/1.1" 200 3197
INFO 2019-04-26 13:41:39,377 basehttp 124 "GET /verify/get_code/??? HTTP/1.1" 200 3354
INFO 2019-04-26 13:42:24,041 basehttp 124 "GET /user/signin/ HTTP/1.1" 200 13482
INFO 2019-04-26 13:42:24,182 basehttp 124 "GET /verify/get_code/ HTTP/1.1" 200 3209
INFO 2019-04-26 13:42:49,749 basehttp 124 "GET /user/signin/ HTTP/1.1" 200 13482
INFO 2019-04-26 13:42:49,902 basehttp 124 "GET /verify/get_code/ HTTP/1.1" 200 3356
INFO 2019-04-26 13:43:00,303 basehttp 124 "GET /user/signin/ HTTP/1.1" 200 13495
INFO 2019-04-26 13:43:00,442 basehttp 124 "GET /verify/get_code/ HTTP/1.1" 200 3364
INFO 2019-04-26 13:43:25,033 basehttp 124 "GET /user/signin/ HTTP/1.1" 200 13504
INFO 2019-04-26 13:43:25,185 basehttp 124 "GET /verify/get_code/ HTTP/1.1" 200 3297
INFO 2019-04-26 13:43:27,836 basehttp 124 "POST /verify/check_code/ HTTP/1.1" 200 59
INFO 2019-04-26 13:43:32,476 basehttp 124 "POST /verify/check_code/ HTTP/1.1" 200 59
INFO 2019-04-26 13:43:33,832 basehttp 124 "GET /verify/get_code/? HTTP/1.1" 200 3387
INFO 2019-04-26 13:43:37,969 basehttp 124 "POST /verify/check_code/ HTTP/1.1" 200 25
INFO 2019-04-26 14:00:11,117 basehttp 124 "GET /user/signup/ HTTP/1.1" 200 17265
INFO 2019-04-26 14:00:11,294 basehttp 124 "GET /verify/get_code/ HTTP/1.1" 200 3291
INFO 2019-04-26 14:00:17,713 basehttp 124 "POST /user/signup/ HTTP/1.1" 200 17814
INFO 2019-04-26 14:00:17,925 basehttp 124 "GET /verify/get_code/ HTTP/1.1" 200 3163
INFO 2019-04-26 14:00:38,364 basehttp 124 "POST /user/check_username/ HTTP/1.1" 200 27
INFO 2019-04-26 14:00:49,852 basehttp 124 "POST /user/check_mobile/ HTTP/1.1" 200 27
INFO 2019-04-26 14:00:49,917 basehttp 124 "GET /verify/get_code/? HTTP/1.1" 200 3108
INFO 2019-04-26 14:00:54,152 basehttp 124 "POST /verify/check_code/ HTTP/1.1" 200 25
INFO 2019-04-26 14:00:54,376 basehttp 124 "POST /user/signup/ HTTP/1.1" 200 13865
INFO 2019-04-26 14:00:54,468 basehttp 124 "GET /verify/get_code/ HTTP/1.1" 200 2864
ERROR 2019-04-26 14:24:14,412 exception 118 Internal Server Error: /user/signup/
Traceback (most recent call last):
  File "/home/binbin/.virtualenvs/v2ex/lib/python3.6/site-packages/django/db/backends/utils.py", line 85, in _execute
    return self.cursor.execute(sql, params)
  File "/home/binbin/.virtualenvs/v2ex/lib/python3.6/site-packages/django/db/backends/mysql/base.py", line 71, in execute
    return self.cursor.execute(query, args)
  File "/home/binbin/.virtualenvs/v2ex/lib/python3.6/site-packages/pymysql/cursors.py", line 165, in execute
    result = self._query(query)
  File "/home/binbin/.virtualenvs/v2ex/lib/python3.6/site-packages/pymysql/cursors.py", line 321, in _query
    conn.query(q)
  File "/home/binbin/.virtualenvs/v2ex/lib/python3.6/site-packages/pymysql/connections.py", line 860, in query
    self._affected_rows = self._read_query_result(unbuffered=unbuffered)
  File "/home/binbin/.virtualenvs/v2ex/lib/python3.6/site-packages/pymysql/connections.py", line 1061, in _read_query_result
    result.read()
  File "/home/binbin/.virtualenvs/v2ex/lib/python3.6/site-packages/pymysql/connections.py", line 1349, in read
    first_packet = self.connection._read_packet()
  File "/home/binbin/.virtualenvs/v2ex/lib/python3.6/site-packages/pymysql/connections.py", line 1018, in _read_packet
    packet.check_error()
  File "/home/binbin/.virtualenvs/v2ex/lib/python3.6/site-packages/pymysql/connections.py", line 384, in check_error
    err.raise_mysql_exception(self._data)
  File "/home/binbin/.virtualenvs/v2ex/lib/python3.6/site-packages/pymysql/err.py", line 107, in raise_mysql_exception
    raise errorclass(errno, errval)
pymysql.err.IntegrityError: (1062, "Duplicate entry 'asdfs' for key 'username'")

The above exception was the direct cause of the following exception:

Traceback (most recent call last):
  File "/home/binbin/.virtualenvs/v2ex/lib/python3.6/site-packages/django/core/handlers/exception.py", line 35, in inner
    response = get_response(request)
  File "/home/binbin/.virtualenvs/v2ex/lib/python3.6/site-packages/django/core/handlers/base.py", line 128, in _get_response
    response = self.process_exception_by_middleware(e, request)
  File "/home/binbin/.virtualenvs/v2ex/lib/python3.6/site-packages/django/core/handlers/base.py", line 126, in _get_response
    response = wrapped_callback(request, *callback_args, **callback_kwargs)
  File "/home/binbin/.virtualenvs/v2ex/lib/python3.6/site-packages/django/views/generic/base.py", line 69, in view
    return self.dispatch(request, *args, **kwargs)
  File "/home/binbin/.virtualenvs/v2ex/lib/python3.6/site-packages/django/views/generic/base.py", line 89, in dispatch
    return handler(request, *args, **kwargs)
  File "/home/binbin/Desktop/Fake/users/views.py", line 68, in post
    user.save()
  File "/home/binbin/.virtualenvs/v2ex/lib/python3.6/site-packages/django/contrib/auth/base_user.py", line 73, in save
    super().save(*args, **kwargs)
  File "/home/binbin/.virtualenvs/v2ex/lib/python3.6/site-packages/django/db/models/base.py", line 729, in save
    force_update=force_update, update_fields=update_fields)
  File "/home/binbin/.virtualenvs/v2ex/lib/python3.6/site-packages/django/db/models/base.py", line 759, in save_base
    updated = self._save_table(raw, cls, force_insert, force_update, using, update_fields)
  File "/home/binbin/.virtualenvs/v2ex/lib/python3.6/site-packages/django/db/models/base.py", line 842, in _save_table
    result = self._do_insert(cls._base_manager, using, fields, update_pk, raw)
  File "/home/binbin/.virtualenvs/v2ex/lib/python3.6/site-packages/django/db/models/base.py", line 880, in _do_insert
    using=using, raw=raw)
  File "/home/binbin/.virtualenvs/v2ex/lib/python3.6/site-packages/django/db/models/manager.py", line 82, in manager_method
    return getattr(self.get_queryset(), name)(*args, **kwargs)
  File "/home/binbin/.virtualenvs/v2ex/lib/python3.6/site-packages/django/db/models/query.py", line 1125, in _insert
    return query.get_compiler(using=using).execute_sql(return_id)
  File "/home/binbin/.virtualenvs/v2ex/lib/python3.6/site-packages/django/db/models/sql/compiler.py", line 1281, in execute_sql
    cursor.execute(sql, params)
  File "/home/binbin/.virtualenvs/v2ex/lib/python3.6/site-packages/django/db/backends/utils.py", line 100, in execute
    return super().execute(sql, params)
  File "/home/binbin/.virtualenvs/v2ex/lib/python3.6/site-packages/django/db/backends/utils.py", line 68, in execute
    return self._execute_with_wrappers(sql, params, many=False, executor=self._execute)
  File "/home/binbin/.virtualenvs/v2ex/lib/python3.6/site-packages/django/db/backends/utils.py", line 77, in _execute_with_wrappers
    return executor(sql, params, many, context)
  File "/home/binbin/.virtualenvs/v2ex/lib/python3.6/site-packages/django/db/backends/utils.py", line 85, in _execute
    return self.cursor.execute(sql, params)
  File "/home/binbin/.virtualenvs/v2ex/lib/python3.6/site-packages/django/db/utils.py", line 89, in __exit__
    raise dj_exc_value.with_traceback(traceback) from exc_value
  File "/home/binbin/.virtualenvs/v2ex/lib/python3.6/site-packages/django/db/backends/utils.py", line 85, in _execute
    return self.cursor.execute(sql, params)
  File "/home/binbin/.virtualenvs/v2ex/lib/python3.6/site-packages/django/db/backends/mysql/base.py", line 71, in execute
    return self.cursor.execute(query, args)
  File "/home/binbin/.virtualenvs/v2ex/lib/python3.6/site-packages/pymysql/cursors.py", line 165, in execute
    result = self._query(query)
  File "/home/binbin/.virtualenvs/v2ex/lib/python3.6/site-packages/pymysql/cursors.py", line 321, in _query
    conn.query(q)
  File "/home/binbin/.virtualenvs/v2ex/lib/python3.6/site-packages/pymysql/connections.py", line 860, in query
    self._affected_rows = self._read_query_result(unbuffered=unbuffered)
  File "/home/binbin/.virtualenvs/v2ex/lib/python3.6/site-packages/pymysql/connections.py", line 1061, in _read_query_result
    result.read()
  File "/home/binbin/.virtualenvs/v2ex/lib/python3.6/site-packages/pymysql/connections.py", line 1349, in read
    first_packet = self.connection._read_packet()
  File "/home/binbin/.virtualenvs/v2ex/lib/python3.6/site-packages/pymysql/connections.py", line 1018, in _read_packet
    packet.check_error()
  File "/home/binbin/.virtualenvs/v2ex/lib/python3.6/site-packages/pymysql/connections.py", line 384, in check_error
    err.raise_mysql_exception(self._data)
  File "/home/binbin/.virtualenvs/v2ex/lib/python3.6/site-packages/pymysql/err.py", line 107, in raise_mysql_exception
    raise errorclass(errno, errval)
django.db.utils.IntegrityError: (1062, "Duplicate entry 'asdfs' for key 'username'")
ERROR 2019-04-26 14:24:14,636 basehttp 124 "POST /user/signup/ HTTP/1.1" 500 243855
ERROR 2019-04-26 14:25:07,431 exception 118 Internal Server Error: /user/signup/
Traceback (most recent call last):
  File "/home/binbin/.virtualenvs/v2ex/lib/python3.6/site-packages/django/db/backends/utils.py", line 85, in _execute
    return self.cursor.execute(sql, params)
  File "/home/binbin/.virtualenvs/v2ex/lib/python3.6/site-packages/django/db/backends/mysql/base.py", line 71, in execute
    return self.cursor.execute(query, args)
  File "/home/binbin/.virtualenvs/v2ex/lib/python3.6/site-packages/pymysql/cursors.py", line 165, in execute
    result = self._query(query)
  File "/home/binbin/.virtualenvs/v2ex/lib/python3.6/site-packages/pymysql/cursors.py", line 321, in _query
    conn.query(q)
  File "/home/binbin/.virtualenvs/v2ex/lib/python3.6/site-packages/pymysql/connections.py", line 860, in query
    self._affected_rows = self._read_query_result(unbuffered=unbuffered)
  File "/home/binbin/.virtualenvs/v2ex/lib/python3.6/site-packages/pymysql/connections.py", line 1061, in _read_query_result
    result.read()
  File "/home/binbin/.virtualenvs/v2ex/lib/python3.6/site-packages/pymysql/connections.py", line 1349, in read
    first_packet = self.connection._read_packet()
  File "/home/binbin/.virtualenvs/v2ex/lib/python3.6/site-packages/pymysql/connections.py", line 1018, in _read_packet
    packet.check_error()
  File "/home/binbin/.virtualenvs/v2ex/lib/python3.6/site-packages/pymysql/connections.py", line 384, in check_error
    err.raise_mysql_exception(self._data)
  File "/home/binbin/.virtualenvs/v2ex/lib/python3.6/site-packages/pymysql/err.py", line 107, in raise_mysql_exception
    raise errorclass(errno, errval)
pymysql.err.IntegrityError: (1062, "Duplicate entry 'asdfs' for key 'username'")

The above exception was the direct cause of the following exception:

Traceback (most recent call last):
  File "/home/binbin/.virtualenvs/v2ex/lib/python3.6/site-packages/django/core/handlers/exception.py", line 35, in inner
    response = get_response(request)
  File "/home/binbin/.virtualenvs/v2ex/lib/python3.6/site-packages/django/core/handlers/base.py", line 128, in _get_response
    response = self.process_exception_by_middleware(e, request)
  File "/home/binbin/.virtualenvs/v2ex/lib/python3.6/site-packages/django/core/handlers/base.py", line 126, in _get_response
    response = wrapped_callback(request, *callback_args, **callback_kwargs)
  File "/home/binbin/.virtualenvs/v2ex/lib/python3.6/site-packages/django/views/generic/base.py", line 69, in view
    return self.dispatch(request, *args, **kwargs)
  File "/home/binbin/.virtualenvs/v2ex/lib/python3.6/site-packages/django/views/generic/base.py", line 89, in dispatch
    return handler(request, *args, **kwargs)
  File "/home/binbin/Desktop/Fake/users/views.py", line 68, in post
    user.save()
  File "/home/binbin/.virtualenvs/v2ex/lib/python3.6/site-packages/django/contrib/auth/base_user.py", line 73, in save
    super().save(*args, **kwargs)
  File "/home/binbin/.virtualenvs/v2ex/lib/python3.6/site-packages/django/db/models/base.py", line 729, in save
    force_update=force_update, update_fields=update_fields)
  File "/home/binbin/.virtualenvs/v2ex/lib/python3.6/site-packages/django/db/models/base.py", line 759, in save_base
    updated = self._save_table(raw, cls, force_insert, force_update, using, update_fields)
  File "/home/binbin/.virtualenvs/v2ex/lib/python3.6/site-packages/django/db/models/base.py", line 842, in _save_table
    result = self._do_insert(cls._base_manager, using, fields, update_pk, raw)
  File "/home/binbin/.virtualenvs/v2ex/lib/python3.6/site-packages/django/db/models/base.py", line 880, in _do_insert
    using=using, raw=raw)
  File "/home/binbin/.virtualenvs/v2ex/lib/python3.6/site-packages/django/db/models/manager.py", line 82, in manager_method
    return getattr(self.get_queryset(), name)(*args, **kwargs)
  File "/home/binbin/.virtualenvs/v2ex/lib/python3.6/site-packages/django/db/models/query.py", line 1125, in _insert
    return query.get_compiler(using=using).execute_sql(return_id)
  File "/home/binbin/.virtualenvs/v2ex/lib/python3.6/site-packages/django/db/models/sql/compiler.py", line 1281, in execute_sql
    cursor.execute(sql, params)
  File "/home/binbin/.virtualenvs/v2ex/lib/python3.6/site-packages/django/db/backends/utils.py", line 100, in execute
    return super().execute(sql, params)
  File "/home/binbin/.virtualenvs/v2ex/lib/python3.6/site-packages/django/db/backends/utils.py", line 68, in execute
    return self._execute_with_wrappers(sql, params, many=False, executor=self._execute)
  File "/home/binbin/.virtualenvs/v2ex/lib/python3.6/site-packages/django/db/backends/utils.py", line 77, in _execute_with_wrappers
    return executor(sql, params, many, context)
  File "/home/binbin/.virtualenvs/v2ex/lib/python3.6/site-packages/django/db/backends/utils.py", line 85, in _execute
    return self.cursor.execute(sql, params)
  File "/home/binbin/.virtualenvs/v2ex/lib/python3.6/site-packages/django/db/utils.py", line 89, in __exit__
    raise dj_exc_value.with_traceback(traceback) from exc_value
  File "/home/binbin/.virtualenvs/v2ex/lib/python3.6/site-packages/django/db/backends/utils.py", line 85, in _execute
    return self.cursor.execute(sql, params)
  File "/home/binbin/.virtualenvs/v2ex/lib/python3.6/site-packages/django/db/backends/mysql/base.py", line 71, in execute
    return self.cursor.execute(query, args)
  File "/home/binbin/.virtualenvs/v2ex/lib/python3.6/site-packages/pymysql/cursors.py", line 165, in execute
    result = self._query(query)
  File "/home/binbin/.virtualenvs/v2ex/lib/python3.6/site-packages/pymysql/cursors.py", line 321, in _query
    conn.query(q)
  File "/home/binbin/.virtualenvs/v2ex/lib/python3.6/site-packages/pymysql/connections.py", line 860, in query
    self._affected_rows = self._read_query_result(unbuffered=unbuffered)
  File "/home/binbin/.virtualenvs/v2ex/lib/python3.6/site-packages/pymysql/connections.py", line 1061, in _read_query_result
    result.read()
  File "/home/binbin/.virtualenvs/v2ex/lib/python3.6/site-packages/pymysql/connections.py", line 1349, in read
    first_packet = self.connection._read_packet()
  File "/home/binbin/.virtualenvs/v2ex/lib/python3.6/site-packages/pymysql/connections.py", line 1018, in _read_packet
    packet.check_error()
  File "/home/binbin/.virtualenvs/v2ex/lib/python3.6/site-packages/pymysql/connections.py", line 384, in check_error
    err.raise_mysql_exception(self._data)
  File "/home/binbin/.virtualenvs/v2ex/lib/python3.6/site-packages/pymysql/err.py", line 107, in raise_mysql_exception
    raise errorclass(errno, errval)
django.db.utils.IntegrityError: (1062, "Duplicate entry 'asdfs' for key 'username'")
ERROR 2019-04-26 14:25:07,741 basehttp 124 "POST /user/signup/ HTTP/1.1" 500 243855
INFO 2019-04-26 14:25:38,415 basehttp 124 "POST /user/signup/ HTTP/1.1" 200 17814
INFO 2019-04-26 14:25:38,519 basehttp 124 "GET /verify/get_code/ HTTP/1.1" 200 3348
INFO 2019-04-26 14:25:41,661 basehttp 124 "POST /user/signup/ HTTP/1.1" 200 17814
INFO 2019-04-26 14:25:41,763 basehttp 124 "GET /verify/get_code/ HTTP/1.1" 200 3238
INFO 2019-04-26 14:25:48,523 basehttp 124 "POST /user/signup/ HTTP/1.1" 200 17814
INFO 2019-04-26 14:25:48,649 basehttp 124 "GET /verify/get_code/ HTTP/1.1" 200 3380
INFO 2019-04-26 14:25:52,223 basehttp 124 "GET /user/signup/ HTTP/1.1" 200 17265
INFO 2019-04-26 14:25:52,524 basehttp 124 "GET /verify/get_code/ HTTP/1.1" 200 3595
INFO 2019-04-26 14:25:55,898 basehttp 124 "GET /user/signup/ HTTP/1.1" 200 17265
INFO 2019-04-26 14:25:56,014 basehttp 124 "GET /verify/get_code/ HTTP/1.1" 200 3141
INFO 2019-04-26 14:25:59,219 basehttp 124 "GET /user/signin/ HTTP/1.1" 200 13865
INFO 2019-04-26 14:25:59,353 basehttp 124 "GET /verify/get_code/ HTTP/1.1" 200 2902
INFO 2019-04-26 14:26:01,801 basehttp 124 "GET /user/signin/ HTTP/1.1" 200 13865
INFO 2019-04-26 14:26:01,918 basehttp 124 "GET /verify/get_code/ HTTP/1.1" 200 3295
ERROR 2019-04-26 14:26:14,073 exception 118 Internal Server Error: /user/signin/
Traceback (most recent call last):
  File "/home/binbin/.virtualenvs/v2ex/lib/python3.6/site-packages/django/core/handlers/exception.py", line 35, in inner
    response = get_response(request)
  File "/home/binbin/.virtualenvs/v2ex/lib/python3.6/site-packages/django/core/handlers/base.py", line 139, in _get_response
    "returned None instead." % (callback.__module__, view_name)
ValueError: The view users.views.SigninView didn't return an HttpResponse object. It returned None instead.
ERROR 2019-04-26 14:26:14,172 basehttp 124 "POST /user/signin/ HTTP/1.1" 500 61626
INFO 2019-04-26 14:28:21,407 basehttp 124 "GET /user/signin/ HTTP/1.1" 200 13536
INFO 2019-04-26 14:28:21,508 basehttp 124 "GET /verify/get_code/ HTTP/1.1" 200 3163
INFO 2019-04-26 14:28:22,618 basehttp 124 "GET /user/signin/ HTTP/1.1" 200 13536
INFO 2019-04-26 14:28:22,803 basehttp 124 "GET /verify/get_code/ HTTP/1.1" 200 3237
ERROR 2019-04-26 14:28:26,583 exception 118 Internal Server Error: /user/signin/
Traceback (most recent call last):
  File "/home/binbin/.virtualenvs/v2ex/lib/python3.6/site-packages/django/core/handlers/exception.py", line 35, in inner
    response = get_response(request)
  File "/home/binbin/.virtualenvs/v2ex/lib/python3.6/site-packages/django/core/handlers/base.py", line 139, in _get_response
    "returned None instead." % (callback.__module__, view_name)
ValueError: The view users.views.SigninView didn't return an HttpResponse object. It returned None instead.
ERROR 2019-04-26 14:28:26,679 basehttp 124 "POST /user/signin/ HTTP/1.1" 500 61624
INFO 2019-04-26 14:29:52,830 basehttp 124 "GET /user/signin/ HTTP/1.1" 200 13524
INFO 2019-04-26 14:29:53,007 basehttp 124 "GET /verify/get_code/ HTTP/1.1" 200 3180
INFO 2019-04-26 14:29:53,918 basehttp 124 "GET /user/signin/ HTTP/1.1" 200 13524
INFO 2019-04-26 14:29:54,065 basehttp 124 "GET /verify/get_code/ HTTP/1.1" 200 3593
INFO 2019-04-26 14:29:56,400 basehttp 124 "POST /user/signin/ HTTP/1.1" 200 13900
INFO 2019-04-26 14:29:56,514 basehttp 124 "GET /verify/get_code/ HTTP/1.1" 200 2856
INFO 2019-04-26 14:30:02,981 basehttp 124 "POST /user/signin/ HTTP/1.1" 200 13822
INFO 2019-04-26 14:30:03,161 basehttp 124 "GET /verify/get_code/ HTTP/1.1" 200 3045
INFO 2019-04-26 14:30:11,255 basehttp 124 "POST /user/signin/ HTTP/1.1" 200 13826
INFO 2019-04-26 14:30:11,431 basehttp 124 "GET /verify/get_code/ HTTP/1.1" 200 3277
INFO 2019-04-26 14:30:17,623 basehttp 124 "POST /user/signin/ HTTP/1.1" 200 13749
INFO 2019-04-26 14:30:17,717 basehttp 124 "GET /verify/get_code/ HTTP/1.1" 200 2975
INFO 2019-04-26 14:32:33,596 basehttp 124 "POST /user/signin/ HTTP/1.1" 200 13825
INFO 2019-04-26 14:32:33,734 basehttp 124 "GET /verify/get_code/ HTTP/1.1" 200 3369
INFO 2019-04-26 14:32:35,877 basehttp 124 "POST /user/signin/ HTTP/1.1" 200 13825
INFO 2019-04-26 14:32:35,972 basehttp 124 "GET /verify/get_code/ HTTP/1.1" 200 3022
INFO 2019-04-26 14:32:38,404 basehttp 124 "GET /user/signin/ HTTP/1.1" 200 13524
INFO 2019-04-26 14:32:38,510 basehttp 124 "GET /verify/get_code/ HTTP/1.1" 200 3132
INFO 2019-04-26 14:32:45,212 basehttp 124 "POST /user/signin/ HTTP/1.1" 200 13825
INFO 2019-04-26 14:32:45,393 basehttp 124 "GET /verify/get_code/ HTTP/1.1" 200 3124
INFO 2019-04-26 14:32:53,432 basehttp 124 "POST /verify/check_code/ HTTP/1.1" 200 59
INFO 2019-04-26 14:32:57,655 basehttp 124 "POST /verify/check_code/ HTTP/1.1" 200 59
INFO 2019-04-26 14:32:58,744 basehttp 124 "GET /verify/get_code/? HTTP/1.1" 200 3464
INFO 2019-04-26 14:33:01,861 basehttp 124 "POST /verify/check_code/ HTTP/1.1" 200 25
INFO 2019-04-26 14:33:01,982 basehttp 124 "POST /user/signin/ HTTP/1.1" 200 13825
INFO 2019-04-26 14:33:02,181 basehttp 124 "GET /verify/get_code/ HTTP/1.1" 200 3124
INFO 2019-04-26 14:33:13,513 basehttp 124 "GET /verify/get_code/? HTTP/1.1" 200 3156
INFO 2019-04-26 14:33:16,469 basehttp 124 "POST /verify/check_code/ HTTP/1.1" 200 25
INFO 2019-04-26 14:33:16,610 basehttp 124 "POST /user/signin/ HTTP/1.1" 200 13825
INFO 2019-04-26 14:33:16,693 basehttp 124 "GET /verify/get_code/ HTTP/1.1" 200 2606
INFO 2019-04-26 14:34:01,156 basehttp 124 "POST /verify/check_code/ HTTP/1.1" 200 59
INFO 2019-04-26 14:34:01,776 basehttp 124 "POST /user/signin/ HTTP/1.1" 200 13825
INFO 2019-04-26 14:34:01,911 basehttp 124 "GET /verify/get_code/ HTTP/1.1" 200 3463
INFO 2019-04-26 14:34:09,397 basehttp 124 "POST /verify/check_code/ HTTP/1.1" 200 25
INFO 2019-04-26 14:34:09,504 basehttp 124 "POST /user/signin/ HTTP/1.1" 200 13825
INFO 2019-04-26 14:34:09,698 basehttp 124 "GET /verify/get_code/ HTTP/1.1" 200 3451
INFO 2019-04-26 14:34:14,337 basehttp 124 "POST /user/signin/ HTTP/1.1" 200 13825
INFO 2019-04-26 14:34:14,434 basehttp 124 "GET /verify/get_code/ HTTP/1.1" 200 2987
INFO 2019-04-26 14:34:19,593 basehttp 124 "GET /user/signin/ HTTP/1.1" 200 13524
INFO 2019-04-26 14:34:19,791 basehttp 124 "GET /verify/get_code/ HTTP/1.1" 200 3396
INFO 2019-04-26 14:34:25,059 basehttp 124 "POST /user/signin/ HTTP/1.1" 200 13825
INFO 2019-04-26 14:34:25,162 basehttp 124 "GET /verify/get_code/ HTTP/1.1" 200 2802
INFO 2019-04-26 14:35:21,929 basehttp 124 "POST /verify/check_code/ HTTP/1.1" 200 25
INFO 2019-04-26 14:35:22,693 basehttp 124 "POST /user/signin/ HTTP/1.1" 200 13825
INFO 2019-04-26 14:35:22,825 basehttp 124 "GET /verify/get_code/ HTTP/1.1" 200 3243
INFO 2019-04-26 14:35:41,968 basehttp 124 "POST /verify/check_code/ HTTP/1.1" 200 25
INFO 2019-04-26 14:35:42,000 basehttp 124 "POST /user/signin/ HTTP/1.1" 200 13825
INFO 2019-04-26 14:35:42,156 basehttp 124 "GET /verify/get_code/ HTTP/1.1" 200 3534
INFO 2019-04-26 14:37:10,037 basehttp 124 "POST /user/signin/ HTTP/1.1" 200 13825
INFO 2019-04-26 14:37:13,127 basehttp 124 "GET /user/signin/ HTTP/1.1" 200 13524
INFO 2019-04-26 14:37:13,297 basehttp 124 "GET /verify/get_code/ HTTP/1.1" 200 3596
INFO 2019-04-26 14:37:27,394 basehttp 124 "POST /verify/check_code/ HTTP/1.1" 200 25
INFO 2019-04-26 14:37:27,520 basehttp 124 "POST /user/signin/ HTTP/1.1" 200 13825
INFO 2019-04-26 14:37:27,648 basehttp 124 "GET /verify/get_code/ HTTP/1.1" 200 3088
INFO 2019-04-26 14:38:13,330 basehttp 124 "POST /user/signin/ HTTP/1.1" 200 13749
INFO 2019-04-26 14:38:13,418 basehttp 124 "GET /verify/get_code/ HTTP/1.1" 200 3328
INFO 2019-04-26 14:38:13,892 basehttp 124 "POST /user/signin/ HTTP/1.1" 200 13749
INFO 2019-04-26 14:38:14,255 basehttp 124 "GET /verify/get_code/ HTTP/1.1" 200 2986
INFO 2019-04-26 14:38:14,324 basehttp 124 "POST /user/signin/ HTTP/1.1" 200 13749
INFO 2019-04-26 14:38:14,664 basehttp 124 "GET /verify/get_code/ HTTP/1.1" 200 3361
INFO 2019-04-26 14:38:18,735 basehttp 124 "POST /user/signin/ HTTP/1.1" 200 13825
INFO 2019-04-26 14:38:18,852 basehttp 124 "GET /verify/get_code/ HTTP/1.1" 200 3416
INFO 2019-04-26 14:38:21,951 basehttp 124 "GET /user/signin/ HTTP/1.1" 200 13524
INFO 2019-04-26 14:38:22,071 basehttp 124 "GET /verify/get_code/ HTTP/1.1" 200 3254
INFO 2019-04-26 14:38:23,881 basehttp 124 "POST /user/signin/ HTTP/1.1" 200 13825
INFO 2019-04-26 14:38:24,046 basehttp 124 "GET /verify/get_code/ HTTP/1.1" 200 2926
INFO 2019-04-26 14:38:33,312 basehttp 124 "POST /verify/check_code/ HTTP/1.1" 200 25
INFO 2019-04-26 14:38:33,467 basehttp 124 "POST /user/signin/ HTTP/1.1" 200 13822
INFO 2019-04-26 14:38:33,539 basehttp 124 "GET /verify/get_code/ HTTP/1.1" 200 3084
INFO 2019-04-26 14:38:52,080 basehttp 124 "POST /verify/check_code/ HTTP/1.1" 200 59
INFO 2019-04-26 14:38:52,219 basehttp 124 "POST /user/signin/ HTTP/1.1" 200 13826
INFO 2019-04-26 14:38:52,323 basehttp 124 "GET /verify/get_code/ HTTP/1.1" 200 3486
INFO 2019-04-26 14:39:06,809 basehttp 124 "POST /verify/check_code/ HTTP/1.1" 200 59
INFO 2019-04-26 14:39:06,941 basehttp 124 "POST /user/signin/ HTTP/1.1" 200 13749
INFO 2019-04-26 14:39:07,028 basehttp 124 "GET /verify/get_code/ HTTP/1.1" 200 3050
INFO 2019-04-26 14:39:55,301 basehttp 124 "POST /verify/check_code/ HTTP/1.1" 200 25
INFO 2019-04-26 14:39:55,414 basehttp 124 "POST /user/signin/ HTTP/1.1" 200 13749
INFO 2019-04-26 14:39:55,515 basehttp 124 "GET /verify/get_code/ HTTP/1.1" 200 3052
INFO 2019-04-26 14:44:13,523 basehttp 124 "GET /user/signin/ HTTP/1.1" 200 13524
INFO 2019-04-26 14:44:13,653 basehttp 124 "GET /verify/get_code/ HTTP/1.1" 200 3162
INFO 2019-04-26 14:44:15,431 basehttp 124 "GET /user/signin/ HTTP/1.1" 200 13524
INFO 2019-04-26 14:44:15,563 basehttp 124 "GET /verify/get_code/ HTTP/1.1" 200 3560
INFO 2019-04-26 14:44:26,702 basehttp 124 "POST /verify/check_code/ HTTP/1.1" 200 59
ERROR 2019-04-26 14:44:26,819 exception 118 Internal Server Error: /user/signin/
Traceback (most recent call last):
  File "/home/binbin/.virtualenvs/v2ex/lib/python3.6/site-packages/django/core/handlers/exception.py", line 35, in inner
    response = get_response(request)
  File "/home/binbin/.virtualenvs/v2ex/lib/python3.6/site-packages/django/core/handlers/base.py", line 128, in _get_response
    response = self.process_exception_by_middleware(e, request)
  File "/home/binbin/.virtualenvs/v2ex/lib/python3.6/site-packages/django/core/handlers/base.py", line 126, in _get_response
    response = wrapped_callback(request, *callback_args, **callback_kwargs)
  File "/home/binbin/.virtualenvs/v2ex/lib/python3.6/site-packages/django/views/generic/base.py", line 69, in view
    return self.dispatch(request, *args, **kwargs)
  File "/home/binbin/.virtualenvs/v2ex/lib/python3.6/site-packages/django/views/generic/base.py", line 89, in dispatch
    return handler(request, *args, **kwargs)
  File "/home/binbin/Desktop/Fake/users/views.py", line 90, in post
    if sms_code.upper() != real_sms_code.decode().upper():
AttributeError: 'NoneType' object has no attribute 'decode'
ERROR 2019-04-26 14:44:26,958 basehttp 124 "POST /user/signin/ HTTP/1.1" 500 80906
INFO 2019-04-26 14:44:57,319 basehttp 124 "GET /user/signin/ HTTP/1.1" 200 13524
INFO 2019-04-26 14:44:57,462 basehttp 124 "GET /verify/get_code/ HTTP/1.1" 200 2980
INFO 2019-04-26 14:45:10,082 basehttp 124 "GET /verify/get_code/? HTTP/1.1" 200 3195
INFO 2019-04-26 14:45:15,461 basehttp 124 "POST /verify/check_code/ HTTP/1.1" 200 25
ERROR 2019-04-26 14:45:15,560 exception 118 Internal Server Error: /user/signin/
Traceback (most recent call last):
  File "/home/binbin/.virtualenvs/v2ex/lib/python3.6/site-packages/django/core/handlers/exception.py", line 35, in inner
    response = get_response(request)
  File "/home/binbin/.virtualenvs/v2ex/lib/python3.6/site-packages/django/core/handlers/base.py", line 128, in _get_response
    response = self.process_exception_by_middleware(e, request)
  File "/home/binbin/.virtualenvs/v2ex/lib/python3.6/site-packages/django/core/handlers/base.py", line 126, in _get_response
    response = wrapped_callback(request, *callback_args, **callback_kwargs)
  File "/home/binbin/.virtualenvs/v2ex/lib/python3.6/site-packages/django/views/generic/base.py", line 69, in view
    return self.dispatch(request, *args, **kwargs)
  File "/home/binbin/.virtualenvs/v2ex/lib/python3.6/site-packages/django/views/generic/base.py", line 89, in dispatch
    return handler(request, *args, **kwargs)
  File "/home/binbin/Desktop/Fake/users/views.py", line 90, in post
    if sms_code.upper() != real_sms_code.decode().upper():
AttributeError: 'NoneType' object has no attribute 'decode'
ERROR 2019-04-26 14:45:15,735 basehttp 124 "POST /user/signin/ HTTP/1.1" 500 80906
INFO 2019-04-26 14:46:27,579 basehttp 124 "GET /user/signin/ HTTP/1.1" 200 13524
INFO 2019-04-26 14:46:27,718 basehttp 124 "GET /verify/get_code/ HTTP/1.1" 200 3066
INFO 2019-04-26 14:49:43,314 basehttp 124 "GET /user/signin/ HTTP/1.1" 200 13617
INFO 2019-04-26 14:49:43,471 basehttp 124 "GET /verify/get_code/ HTTP/1.1" 200 3299
INFO 2019-04-26 14:49:45,180 basehttp 124 "GET /user/signin/ HTTP/1.1" 200 13617
INFO 2019-04-26 14:49:45,284 basehttp 124 "GET /verify/get_code/ HTTP/1.1" 200 3559
INFO 2019-04-26 14:49:53,283 basehttp 124 "POST /verify/check_code/ HTTP/1.1" 200 25
ERROR 2019-04-26 14:49:53,346 exception 118 Internal Server Error: /user/signin/
Traceback (most recent call last):
  File "/home/binbin/.virtualenvs/v2ex/lib/python3.6/site-packages/django/core/handlers/exception.py", line 35, in inner
    response = get_response(request)
  File "/home/binbin/.virtualenvs/v2ex/lib/python3.6/site-packages/django/core/handlers/base.py", line 128, in _get_response
    response = self.process_exception_by_middleware(e, request)
  File "/home/binbin/.virtualenvs/v2ex/lib/python3.6/site-packages/django/core/handlers/base.py", line 126, in _get_response
    response = wrapped_callback(request, *callback_args, **callback_kwargs)
  File "/home/binbin/.virtualenvs/v2ex/lib/python3.6/site-packages/django/views/generic/base.py", line 69, in view
    return self.dispatch(request, *args, **kwargs)
  File "/home/binbin/.virtualenvs/v2ex/lib/python3.6/site-packages/django/views/generic/base.py", line 89, in dispatch
    return handler(request, *args, **kwargs)
  File "/home/binbin/Desktop/Fake/users/views.py", line 90, in post
    if sms_code.upper() != real_sms_code.decode().upper():
AttributeError: 'NoneType' object has no attribute 'decode'
ERROR 2019-04-26 14:49:53,485 basehttp 124 "POST /user/signin/ HTTP/1.1" 500 80906
WARNING 2019-05-10 04:29:19,074 base 93 Not Found: /
WARNING 2019-05-10 04:29:19,097 basehttp 124 "GET / HTTP/1.1" 404 2237
WARNING 2019-05-10 04:29:26,938 base 93 Not Found: /favicon.ico
WARNING 2019-05-10 04:29:26,954 basehttp 124 "GET /favicon.ico HTTP/1.1" 404 2288
INFO 2019-05-10 04:29:34,694 basehttp 124 "GET /user/signup/ HTTP/1.1" 200 17265
INFO 2019-05-10 04:29:34,803 basehttp 124 "GET /static/css/bootstrap.css HTTP/1.1" 304 0
INFO 2019-05-10 04:29:34,870 basehttp 124 "GET /static/css/font-awesome.css HTTP/1.1" 304 0
INFO 2019-05-10 04:29:34,885 basehttp 124 "GET /static/plugin/highlight/tomorrow.css HTTP/1.1" 304 0
INFO 2019-05-10 04:29:34,919 basehttp 124 "GET /static/img/fake_logo@2x.png HTTP/1.1" 304 0
INFO 2019-05-10 04:29:35,026 basehttp 124 "GET /verify/get_code/ HTTP/1.1" 200 3339
INFO 2019-05-10 04:29:35,369 basehttp 124 "GET /static/js/jquery-3.3.1.js HTTP/1.1" 304 0
INFO 2019-05-10 04:29:35,396 basehttp 124 "GET /static/js/jquery.cookie.js HTTP/1.1" 304 0
INFO 2019-05-10 04:29:35,420 basehttp 124 "GET /static/js/bootstrap.js HTTP/1.1" 304 0
INFO 2019-05-10 04:29:35,433 basehttp 124 "GET /static/img/qbar_light@2x.png HTTP/1.1" 304 0
INFO 2019-05-10 04:29:35,463 basehttp 124 "GET /static/plugin/highlight/highlight.pack.js HTTP/1.1" 304 0
INFO 2019-05-10 04:29:35,467 basehttp 124 "GET /static/img/shadow_light.png HTTP/1.1" 304 0
INFO 2019-05-10 04:29:42,834 basehttp 124 "GET /user/signin/ HTTP/1.1" 200 13617
INFO 2019-05-10 04:29:43,152 basehttp 124 "GET /verify/get_code/ HTTP/1.1" 200 3269
INFO 2019-05-10 04:32:44,496 basehttp 124 "GET /user/signin/ HTTP/1.1" 200 13617
INFO 2019-05-10 04:32:44,559 basehttp 124 "GET /verify/get_code/ HTTP/1.1" 200 3108
INFO 2019-05-10 04:32:47,394 basehttp 124 "GET /user/signup/ HTTP/1.1" 200 17265
INFO 2019-05-10 04:32:47,468 basehttp 124 "GET /verify/get_code/ HTTP/1.1" 200 3114
INFO 2019-05-10 04:33:05,812 basehttp 124 "POST /user/check_username/ HTTP/1.1" 200 27
INFO 2019-05-10 04:33:12,395 basehttp 124 "POST /user/check_mobile/ HTTP/1.1" 200 67
INFO 2019-05-10 04:33:15,572 basehttp 124 "POST /user/check_mobile/ HTTP/1.1" 200 27
INFO 2019-05-10 04:33:21,611 basehttp 124 "POST /verify/check_code/ HTTP/1.1" 200 25
INFO 2019-05-10 04:33:21,764 basehttp 124 "POST /user/signup/ HTTP/1.1" 200 13617
INFO 2019-05-10 04:33:21,849 basehttp 124 "GET /verify/get_code/ HTTP/1.1" 200 3394
INFO 2019-05-10 04:33:38,433 basehttp 124 "GET /user/signup/ HTTP/1.1" 200 17265
INFO 2019-05-10 04:37:04,534 basehttp 124 "GET /user/signup/ HTTP/1.1" 200 17265
INFO 2019-05-10 04:37:04,605 basehttp 124 "GET /verify/get_code/ HTTP/1.1" 200 3282
INFO 2019-05-10 04:39:52,412 basehttp 124 "POST /user/check_username/ HTTP/1.1" 200 67
INFO 2019-05-10 04:39:57,759 basehttp 124 "POST /user/check_mobile/ HTTP/1.1" 200 67
INFO 2019-05-10 04:40:01,064 basehttp 124 "GET /verify/get_code/? HTTP/1.1" 200 3397
INFO 2019-05-10 04:40:06,618 basehttp 124 "POST /verify/check_code/ HTTP/1.1" 200 25
ERROR 2019-05-10 04:40:06,698 exception 118 Internal Server Error: /user/signup/
Traceback (most recent call last):
  File "/home/binbin/.virtualenvs/v2ex/lib/python3.6/site-packages/django/db/backends/utils.py", line 85, in _execute
    return self.cursor.execute(sql, params)
  File "/home/binbin/.virtualenvs/v2ex/lib/python3.6/site-packages/django/db/backends/mysql/base.py", line 71, in execute
    return self.cursor.execute(query, args)
  File "/home/binbin/.virtualenvs/v2ex/lib/python3.6/site-packages/pymysql/cursors.py", line 165, in execute
    result = self._query(query)
  File "/home/binbin/.virtualenvs/v2ex/lib/python3.6/site-packages/pymysql/cursors.py", line 321, in _query
    conn.query(q)
  File "/home/binbin/.virtualenvs/v2ex/lib/python3.6/site-packages/pymysql/connections.py", line 860, in query
    self._affected_rows = self._read_query_result(unbuffered=unbuffered)
  File "/home/binbin/.virtualenvs/v2ex/lib/python3.6/site-packages/pymysql/connections.py", line 1061, in _read_query_result
    result.read()
  File "/home/binbin/.virtualenvs/v2ex/lib/python3.6/site-packages/pymysql/connections.py", line 1349, in read
    first_packet = self.connection._read_packet()
  File "/home/binbin/.virtualenvs/v2ex/lib/python3.6/site-packages/pymysql/connections.py", line 1018, in _read_packet
    packet.check_error()
  File "/home/binbin/.virtualenvs/v2ex/lib/python3.6/site-packages/pymysql/connections.py", line 384, in check_error
    err.raise_mysql_exception(self._data)
  File "/home/binbin/.virtualenvs/v2ex/lib/python3.6/site-packages/pymysql/err.py", line 107, in raise_mysql_exception
    raise errorclass(errno, errval)
pymysql.err.IntegrityError: (1062, "Duplicate entry 'asdfs' for key 'username'")

The above exception was the direct cause of the following exception:

Traceback (most recent call last):
  File "/home/binbin/.virtualenvs/v2ex/lib/python3.6/site-packages/django/core/handlers/exception.py", line 35, in inner
    response = get_response(request)
  File "/home/binbin/.virtualenvs/v2ex/lib/python3.6/site-packages/django/core/handlers/base.py", line 128, in _get_response
    response = self.process_exception_by_middleware(e, request)
  File "/home/binbin/.virtualenvs/v2ex/lib/python3.6/site-packages/django/core/handlers/base.py", line 126, in _get_response
    response = wrapped_callback(request, *callback_args, **callback_kwargs)
  File "/home/binbin/.virtualenvs/v2ex/lib/python3.6/site-packages/django/views/generic/base.py", line 69, in view
    return self.dispatch(request, *args, **kwargs)
  File "/home/binbin/.virtualenvs/v2ex/lib/python3.6/site-packages/django/views/generic/base.py", line 89, in dispatch
    return handler(request, *args, **kwargs)
  File "/home/binbin/Desktop/Fake/users/views.py", line 69, in post
    user.save()
  File "/home/binbin/.virtualenvs/v2ex/lib/python3.6/site-packages/django/contrib/auth/base_user.py", line 73, in save
    super().save(*args, **kwargs)
  File "/home/binbin/.virtualenvs/v2ex/lib/python3.6/site-packages/django/db/models/base.py", line 729, in save
    force_update=force_update, update_fields=update_fields)
  File "/home/binbin/.virtualenvs/v2ex/lib/python3.6/site-packages/django/db/models/base.py", line 759, in save_base
    updated = self._save_table(raw, cls, force_insert, force_update, using, update_fields)
  File "/home/binbin/.virtualenvs/v2ex/lib/python3.6/site-packages/django/db/models/base.py", line 842, in _save_table
    result = self._do_insert(cls._base_manager, using, fields, update_pk, raw)
  File "/home/binbin/.virtualenvs/v2ex/lib/python3.6/site-packages/django/db/models/base.py", line 880, in _do_insert
    using=using, raw=raw)
  File "/home/binbin/.virtualenvs/v2ex/lib/python3.6/site-packages/django/db/models/manager.py", line 82, in manager_method
    return getattr(self.get_queryset(), name)(*args, **kwargs)
  File "/home/binbin/.virtualenvs/v2ex/lib/python3.6/site-packages/django/db/models/query.py", line 1125, in _insert
    return query.get_compiler(using=using).execute_sql(return_id)
  File "/home/binbin/.virtualenvs/v2ex/lib/python3.6/site-packages/django/db/models/sql/compiler.py", line 1281, in execute_sql
    cursor.execute(sql, params)
  File "/home/binbin/.virtualenvs/v2ex/lib/python3.6/site-packages/django/db/backends/utils.py", line 100, in execute
    return super().execute(sql, params)
  File "/home/binbin/.virtualenvs/v2ex/lib/python3.6/site-packages/django/db/backends/utils.py", line 68, in execute
    return self._execute_with_wrappers(sql, params, many=False, executor=self._execute)
  File "/home/binbin/.virtualenvs/v2ex/lib/python3.6/site-packages/django/db/backends/utils.py", line 77, in _execute_with_wrappers
    return executor(sql, params, many, context)
  File "/home/binbin/.virtualenvs/v2ex/lib/python3.6/site-packages/django/db/backends/utils.py", line 85, in _execute
    return self.cursor.execute(sql, params)
  File "/home/binbin/.virtualenvs/v2ex/lib/python3.6/site-packages/django/db/utils.py", line 89, in __exit__
    raise dj_exc_value.with_traceback(traceback) from exc_value
  File "/home/binbin/.virtualenvs/v2ex/lib/python3.6/site-packages/django/db/backends/utils.py", line 85, in _execute
    return self.cursor.execute(sql, params)
  File "/home/binbin/.virtualenvs/v2ex/lib/python3.6/site-packages/django/db/backends/mysql/base.py", line 71, in execute
    return self.cursor.execute(query, args)
  File "/home/binbin/.virtualenvs/v2ex/lib/python3.6/site-packages/pymysql/cursors.py", line 165, in execute
    result = self._query(query)
  File "/home/binbin/.virtualenvs/v2ex/lib/python3.6/site-packages/pymysql/cursors.py", line 321, in _query
    conn.query(q)
  File "/home/binbin/.virtualenvs/v2ex/lib/python3.6/site-packages/pymysql/connections.py", line 860, in query
    self._affected_rows = self._read_query_result(unbuffered=unbuffered)
  File "/home/binbin/.virtualenvs/v2ex/lib/python3.6/site-packages/pymysql/connections.py", line 1061, in _read_query_result
    result.read()
  File "/home/binbin/.virtualenvs/v2ex/lib/python3.6/site-packages/pymysql/connections.py", line 1349, in read
    first_packet = self.connection._read_packet()
  File "/home/binbin/.virtualenvs/v2ex/lib/python3.6/site-packages/pymysql/connections.py", line 1018, in _read_packet
    packet.check_error()
  File "/home/binbin/.virtualenvs/v2ex/lib/python3.6/site-packages/pymysql/connections.py", line 384, in check_error
    err.raise_mysql_exception(self._data)
  File "/home/binbin/.virtualenvs/v2ex/lib/python3.6/site-packages/pymysql/err.py", line 107, in raise_mysql_exception
    raise errorclass(errno, errval)
django.db.utils.IntegrityError: (1062, "Duplicate entry 'asdfs' for key 'username'")
ERROR 2019-05-10 04:40:07,070 basehttp 124 "POST /user/signup/ HTTP/1.1" 500 243743
INFO 2019-05-10 05:07:01,980 basehttp 124 "GET /user/signup/ HTTP/1.1" 200 17265
INFO 2019-05-10 05:07:02,108 basehttp 124 "GET /verify/get_code/ HTTP/1.1" 200 3197
INFO 2019-05-10 05:07:05,505 basehttp 124 "POST /user/check_username/ HTTP/1.1" 200 67
INFO 2019-05-10 05:07:17,933 basehttp 124 "POST /user/check_mobile/ HTTP/1.1" 200 67
INFO 2019-05-10 05:07:19,640 basehttp 124 "POST /user/check_mobile/ HTTP/1.1" 200 27
INFO 2019-05-10 05:07:24,831 basehttp 124 "POST /verify/check_code/ HTTP/1.1" 200 25
INFO 2019-05-10 05:07:24,948 basehttp 124 "POST /user/signup/ HTTP/1.1" 200 17684
INFO 2019-05-10 05:07:25,047 basehttp 124 "GET /verify/get_code/ HTTP/1.1" 200 3497
INFO 2019-05-10 05:08:10,041 basehttp 124 "GET /static/js/bootstrap.js.map HTTP/1.1" 304 0
INFO 2019-05-10 05:08:10,112 basehttp 124 "GET /static/css/bootstrap.css.map HTTP/1.1" 304 0
INFO 2019-05-10 05:08:10,892 basehttp 124 "POST /user/signup/ HTTP/1.1" 200 17684
INFO 2019-05-10 05:08:10,989 basehttp 124 "GET /verify/get_code/ HTTP/1.1" 200 3129
INFO 2019-05-10 05:08:23,790 basehttp 124 "POST /user/signup/ HTTP/1.1" 200 17684
INFO 2019-05-10 05:08:23,951 basehttp 124 "GET /verify/get_code/ HTTP/1.1" 200 3016
INFO 2019-05-10 05:08:25,394 basehttp 124 "GET /user/signup/ HTTP/1.1" 200 17265
INFO 2019-05-10 05:08:25,497 basehttp 124 "GET /verify/get_code/ HTTP/1.1" 200 3254
INFO 2019-05-10 05:08:27,638 basehttp 124 "POST /user/check_username/ HTTP/1.1" 200 67
INFO 2019-05-10 05:08:38,079 basehttp 124 "POST /user/check_mobile/ HTTP/1.1" 200 27
INFO 2019-05-10 05:08:42,286 basehttp 124 "POST /verify/check_code/ HTTP/1.1" 200 25
INFO 2019-05-10 05:08:42,459 basehttp 124 "POST /user/signup/ HTTP/1.1" 200 17684
INFO 2019-05-10 05:08:42,600 basehttp 124 "GET /verify/get_code/ HTTP/1.1" 200 3255
INFO 2019-05-10 05:12:35,012 basehttp 124 "GET /user/signup/ HTTP/1.1" 200 17265
INFO 2019-05-10 05:12:35,144 basehttp 124 "GET /verify/get_code/ HTTP/1.1" 200 3305
INFO 2019-05-10 05:12:36,732 basehttp 124 "POST /user/check_username/ HTTP/1.1" 200 67
INFO 2019-05-10 05:12:45,285 basehttp 124 "POST /user/check_mobile/ HTTP/1.1" 200 27
INFO 2019-05-10 05:12:50,782 basehttp 124 "POST /verify/check_code/ HTTP/1.1" 200 25
INFO 2019-05-10 05:12:50,939 basehttp 124 "POST /user/signup/ HTTP/1.1" 200 17684
INFO 2019-05-10 05:12:51,099 basehttp 124 "GET /verify/get_code/ HTTP/1.1" 200 3140
INFO 2019-05-10 05:14:31,248 basehttp 124 "GET /user/signup/ HTTP/1.1" 200 17265
INFO 2019-05-10 05:14:31,400 basehttp 124 "GET /verify/get_code/ HTTP/1.1" 200 2905
INFO 2019-05-10 05:14:33,108 basehttp 124 "POST /user/check_username/ HTTP/1.1" 200 67
INFO 2019-05-10 05:14:39,158 basehttp 124 "POST /user/check_mobile/ HTTP/1.1" 200 27
INFO 2019-05-10 05:14:46,036 basehttp 124 "POST /verify/check_code/ HTTP/1.1" 200 25
INFO 2019-05-10 05:14:46,216 basehttp 124 "POST /user/signup/ HTTP/1.1" 200 17699
INFO 2019-05-10 05:14:46,368 basehttp 124 "GET /verify/get_code/ HTTP/1.1" 200 3427
